{
 "cells": [
  {
   "cell_type": "code",
   "execution_count": 2,
   "metadata": {},
   "outputs": [],
   "source": [
    "from keras.datasets import imdb\n",
    "from keras.preprocessing.text import Tokenizer\n",
    "from keras.utils import pad_sequences\n",
    "from keras import Sequential\n",
    "from keras.layers import Dense,SimpleRNN,Embedding,Flatten"
   ]
  },
  {
   "cell_type": "code",
   "execution_count": 3,
   "metadata": {},
   "outputs": [],
   "source": [
    "(X_train,y_train),(X_test,y_test) = imdb.load_data()"
   ]
  },
  {
   "cell_type": "code",
   "execution_count": 4,
   "metadata": {},
   "outputs": [],
   "source": [
    "X_train = pad_sequences(X_train,padding='post',maxlen=50)\n",
    "X_test = pad_sequences(X_test,padding='post',maxlen=50)"
   ]
  },
  {
   "cell_type": "code",
   "execution_count": 5,
   "metadata": {},
   "outputs": [
    {
     "data": {
      "text/plain": [
       "(25000, 50)"
      ]
     },
     "execution_count": 5,
     "metadata": {},
     "output_type": "execute_result"
    }
   ],
   "source": [
    "X_train.shape"
   ]
  },
  {
   "cell_type": "code",
   "execution_count": 7,
   "metadata": {},
   "outputs": [
    {
     "name": "stdout",
     "output_type": "stream",
     "text": [
      "Model: \"sequential_1\"\n",
      "_________________________________________________________________\n",
      " Layer (type)                Output Shape              Param #   \n",
      "=================================================================\n",
      " embedding_1 (Embedding)     (None, 50, 50)            500000    \n",
      "                                                                 \n",
      " simple_rnn (SimpleRNN)      (None, 32)                2656      \n",
      "                                                                 \n",
      " dense (Dense)               (None, 1)                 33        \n",
      "                                                                 \n",
      "=================================================================\n",
      "Total params: 502,689\n",
      "Trainable params: 502,689\n",
      "Non-trainable params: 0\n",
      "_________________________________________________________________\n"
     ]
    }
   ],
   "source": [
    "model = Sequential()\n",
    "model.add(Embedding(input_dim=10000, output_dim=50, input_length=50))\n",
    "model.add(SimpleRNN(32, return_sequences=False))\n",
    "model.add(Dense(1, activation='sigmoid'))\n",
    "\n",
    "model.summary()"
   ]
  },
  {
   "cell_type": "code",
   "execution_count": 11,
   "metadata": {},
   "outputs": [],
   "source": [
    "import numpy as np\n",
    "import tensorflow as tf\n",
    "\n",
    "model.compile(optimizer='adam', loss='binary_crossentropy', metrics=['acc'])\n"
   ]
  },
  {
   "cell_type": "code",
   "execution_count": 15,
   "metadata": {},
   "outputs": [
    {
     "name": "stdout",
     "output_type": "stream",
     "text": [
      "Epoch 1/10\n"
     ]
    },
    {
     "ename": "InvalidArgumentError",
     "evalue": "Graph execution error:\n\nDetected at node 'sequential_1/embedding_1/embedding_lookup' defined at (most recent call last):\n    File \"c:\\Anaconda3\\envs\\TF_D\\lib\\runpy.py\", line 197, in _run_module_as_main\n      return _run_code(code, main_globals, None,\n    File \"c:\\Anaconda3\\envs\\TF_D\\lib\\runpy.py\", line 87, in _run_code\n      exec(code, run_globals)\n    File \"c:\\Anaconda3\\envs\\TF_D\\lib\\site-packages\\ipykernel_launcher.py\", line 18, in <module>\n      app.launch_new_instance()\n    File \"c:\\Anaconda3\\envs\\TF_D\\lib\\site-packages\\traitlets\\config\\application.py\", line 1075, in launch_instance\n      app.start()\n    File \"c:\\Anaconda3\\envs\\TF_D\\lib\\site-packages\\ipykernel\\kernelapp.py\", line 739, in start\n      self.io_loop.start()\n    File \"c:\\Anaconda3\\envs\\TF_D\\lib\\site-packages\\tornado\\platform\\asyncio.py\", line 205, in start\n      self.asyncio_loop.run_forever()\n    File \"c:\\Anaconda3\\envs\\TF_D\\lib\\asyncio\\base_events.py\", line 601, in run_forever\n      self._run_once()\n    File \"c:\\Anaconda3\\envs\\TF_D\\lib\\asyncio\\base_events.py\", line 1905, in _run_once\n      handle._run()\n    File \"c:\\Anaconda3\\envs\\TF_D\\lib\\asyncio\\events.py\", line 80, in _run\n      self._context.run(self._callback, *self._args)\n    File \"c:\\Anaconda3\\envs\\TF_D\\lib\\site-packages\\ipykernel\\kernelbase.py\", line 545, in dispatch_queue\n      await self.process_one()\n    File \"c:\\Anaconda3\\envs\\TF_D\\lib\\site-packages\\ipykernel\\kernelbase.py\", line 534, in process_one\n      await dispatch(*args)\n    File \"c:\\Anaconda3\\envs\\TF_D\\lib\\site-packages\\ipykernel\\kernelbase.py\", line 437, in dispatch_shell\n      await result\n    File \"c:\\Anaconda3\\envs\\TF_D\\lib\\site-packages\\ipykernel\\ipkernel.py\", line 362, in execute_request\n      await super().execute_request(stream, ident, parent)\n    File \"c:\\Anaconda3\\envs\\TF_D\\lib\\site-packages\\ipykernel\\kernelbase.py\", line 778, in execute_request\n      reply_content = await reply_content\n    File \"c:\\Anaconda3\\envs\\TF_D\\lib\\site-packages\\ipykernel\\ipkernel.py\", line 449, in do_execute\n      res = shell.run_cell(\n    File \"c:\\Anaconda3\\envs\\TF_D\\lib\\site-packages\\ipykernel\\zmqshell.py\", line 549, in run_cell\n      return super().run_cell(*args, **kwargs)\n    File \"c:\\Anaconda3\\envs\\TF_D\\lib\\site-packages\\IPython\\core\\interactiveshell.py\", line 3048, in run_cell\n      result = self._run_cell(\n    File \"c:\\Anaconda3\\envs\\TF_D\\lib\\site-packages\\IPython\\core\\interactiveshell.py\", line 3103, in _run_cell\n      result = runner(coro)\n    File \"c:\\Anaconda3\\envs\\TF_D\\lib\\site-packages\\IPython\\core\\async_helpers.py\", line 129, in _pseudo_sync_runner\n      coro.send(None)\n    File \"c:\\Anaconda3\\envs\\TF_D\\lib\\site-packages\\IPython\\core\\interactiveshell.py\", line 3308, in run_cell_async\n      has_raised = await self.run_ast_nodes(code_ast.body, cell_name,\n    File \"c:\\Anaconda3\\envs\\TF_D\\lib\\site-packages\\IPython\\core\\interactiveshell.py\", line 3490, in run_ast_nodes\n      if await self.run_code(code, result, async_=asy):\n    File \"c:\\Anaconda3\\envs\\TF_D\\lib\\site-packages\\IPython\\core\\interactiveshell.py\", line 3550, in run_code\n      exec(code_obj, self.user_global_ns, self.user_ns)\n    File \"C:\\Users\\Vandan Patel\\AppData\\Local\\Temp\\ipykernel_23896\\873758998.py\", line 1, in <module>\n      model.fit(X_train, y_train, epochs=5, batch_size=32, validation_data=(X_test, y_test), verbose=2)\n    File \"c:\\Anaconda3\\envs\\TF_D\\lib\\site-packages\\keras\\utils\\traceback_utils.py\", line 65, in error_handler\n      return fn(*args, **kwargs)\n    File \"c:\\Anaconda3\\envs\\TF_D\\lib\\site-packages\\keras\\engine\\training.py\", line 1650, in fit\n      tmp_logs = self.train_function(iterator)\n    File \"c:\\Anaconda3\\envs\\TF_D\\lib\\site-packages\\keras\\engine\\training.py\", line 1249, in train_function\n      return step_function(self, iterator)\n    File \"c:\\Anaconda3\\envs\\TF_D\\lib\\site-packages\\keras\\engine\\training.py\", line 1233, in step_function\n      outputs = model.distribute_strategy.run(run_step, args=(data,))\n    File \"c:\\Anaconda3\\envs\\TF_D\\lib\\site-packages\\keras\\engine\\training.py\", line 1222, in run_step\n      outputs = model.train_step(data)\n    File \"c:\\Anaconda3\\envs\\TF_D\\lib\\site-packages\\keras\\engine\\training.py\", line 1023, in train_step\n      y_pred = self(x, training=True)\n    File \"c:\\Anaconda3\\envs\\TF_D\\lib\\site-packages\\keras\\utils\\traceback_utils.py\", line 65, in error_handler\n      return fn(*args, **kwargs)\n    File \"c:\\Anaconda3\\envs\\TF_D\\lib\\site-packages\\keras\\engine\\training.py\", line 561, in __call__\n      return super().__call__(*args, **kwargs)\n    File \"c:\\Anaconda3\\envs\\TF_D\\lib\\site-packages\\keras\\utils\\traceback_utils.py\", line 65, in error_handler\n      return fn(*args, **kwargs)\n    File \"c:\\Anaconda3\\envs\\TF_D\\lib\\site-packages\\keras\\engine\\base_layer.py\", line 1132, in __call__\n      outputs = call_fn(inputs, *args, **kwargs)\n    File \"c:\\Anaconda3\\envs\\TF_D\\lib\\site-packages\\keras\\utils\\traceback_utils.py\", line 96, in error_handler\n      return fn(*args, **kwargs)\n    File \"c:\\Anaconda3\\envs\\TF_D\\lib\\site-packages\\keras\\engine\\sequential.py\", line 413, in call\n      return super().call(inputs, training=training, mask=mask)\n    File \"c:\\Anaconda3\\envs\\TF_D\\lib\\site-packages\\keras\\engine\\functional.py\", line 511, in call\n      return self._run_internal_graph(inputs, training=training, mask=mask)\n    File \"c:\\Anaconda3\\envs\\TF_D\\lib\\site-packages\\keras\\engine\\functional.py\", line 668, in _run_internal_graph\n      outputs = node.layer(*args, **kwargs)\n    File \"c:\\Anaconda3\\envs\\TF_D\\lib\\site-packages\\keras\\utils\\traceback_utils.py\", line 65, in error_handler\n      return fn(*args, **kwargs)\n    File \"c:\\Anaconda3\\envs\\TF_D\\lib\\site-packages\\keras\\engine\\base_layer.py\", line 1132, in __call__\n      outputs = call_fn(inputs, *args, **kwargs)\n    File \"c:\\Anaconda3\\envs\\TF_D\\lib\\site-packages\\keras\\utils\\traceback_utils.py\", line 96, in error_handler\n      return fn(*args, **kwargs)\n    File \"c:\\Anaconda3\\envs\\TF_D\\lib\\site-packages\\keras\\layers\\core\\embedding.py\", line 208, in call\n      out = tf.nn.embedding_lookup(self.embeddings, inputs)\nNode: 'sequential_1/embedding_1/embedding_lookup'\nindices[0,1] = 14551 is not in [0, 10000)\n\t [[{{node sequential_1/embedding_1/embedding_lookup}}]] [Op:__inference_train_function_6972]",
     "output_type": "error",
     "traceback": [
      "\u001b[1;31m---------------------------------------------------------------------------\u001b[0m",
      "\u001b[1;31mInvalidArgumentError\u001b[0m                      Traceback (most recent call last)",
      "Cell \u001b[1;32mIn[15], line 1\u001b[0m\n\u001b[1;32m----> 1\u001b[0m \u001b[43mmodel\u001b[49m\u001b[38;5;241;43m.\u001b[39;49m\u001b[43mfit\u001b[49m\u001b[43m(\u001b[49m\u001b[43mX_train\u001b[49m\u001b[43m,\u001b[49m\u001b[43m \u001b[49m\u001b[43my_train\u001b[49m\u001b[43m,\u001b[49m\u001b[43m \u001b[49m\u001b[43mepochs\u001b[49m\u001b[38;5;241;43m=\u001b[39;49m\u001b[38;5;241;43m10\u001b[39;49m\u001b[43m,\u001b[49m\u001b[43m \u001b[49m\u001b[43mbatch_size\u001b[49m\u001b[38;5;241;43m=\u001b[39;49m\u001b[38;5;241;43m5\u001b[39;49m\u001b[43m,\u001b[49m\u001b[43m \u001b[49m\u001b[43mvalidation_data\u001b[49m\u001b[38;5;241;43m=\u001b[39;49m\u001b[43m(\u001b[49m\u001b[43mX_test\u001b[49m\u001b[43m,\u001b[49m\u001b[43m \u001b[49m\u001b[43my_test\u001b[49m\u001b[43m)\u001b[49m\u001b[43m)\u001b[49m\n",
      "File \u001b[1;32mc:\\Anaconda3\\envs\\TF_D\\lib\\site-packages\\keras\\utils\\traceback_utils.py:70\u001b[0m, in \u001b[0;36mfilter_traceback.<locals>.error_handler\u001b[1;34m(*args, **kwargs)\u001b[0m\n\u001b[0;32m     67\u001b[0m     filtered_tb \u001b[38;5;241m=\u001b[39m _process_traceback_frames(e\u001b[38;5;241m.\u001b[39m__traceback__)\n\u001b[0;32m     68\u001b[0m     \u001b[38;5;66;03m# To get the full stack trace, call:\u001b[39;00m\n\u001b[0;32m     69\u001b[0m     \u001b[38;5;66;03m# `tf.debugging.disable_traceback_filtering()`\u001b[39;00m\n\u001b[1;32m---> 70\u001b[0m     \u001b[38;5;28;01mraise\u001b[39;00m e\u001b[38;5;241m.\u001b[39mwith_traceback(filtered_tb) \u001b[38;5;28;01mfrom\u001b[39;00m \u001b[38;5;28;01mNone\u001b[39;00m\n\u001b[0;32m     71\u001b[0m \u001b[38;5;28;01mfinally\u001b[39;00m:\n\u001b[0;32m     72\u001b[0m     \u001b[38;5;28;01mdel\u001b[39;00m filtered_tb\n",
      "File \u001b[1;32mc:\\Anaconda3\\envs\\TF_D\\lib\\site-packages\\tensorflow\\python\\eager\\execute.py:52\u001b[0m, in \u001b[0;36mquick_execute\u001b[1;34m(op_name, num_outputs, inputs, attrs, ctx, name)\u001b[0m\n\u001b[0;32m     50\u001b[0m \u001b[38;5;28;01mtry\u001b[39;00m:\n\u001b[0;32m     51\u001b[0m   ctx\u001b[38;5;241m.\u001b[39mensure_initialized()\n\u001b[1;32m---> 52\u001b[0m   tensors \u001b[38;5;241m=\u001b[39m pywrap_tfe\u001b[38;5;241m.\u001b[39mTFE_Py_Execute(ctx\u001b[38;5;241m.\u001b[39m_handle, device_name, op_name,\n\u001b[0;32m     53\u001b[0m                                       inputs, attrs, num_outputs)\n\u001b[0;32m     54\u001b[0m \u001b[38;5;28;01mexcept\u001b[39;00m core\u001b[38;5;241m.\u001b[39m_NotOkStatusException \u001b[38;5;28;01mas\u001b[39;00m e:\n\u001b[0;32m     55\u001b[0m   \u001b[38;5;28;01mif\u001b[39;00m name \u001b[38;5;129;01mis\u001b[39;00m \u001b[38;5;129;01mnot\u001b[39;00m \u001b[38;5;28;01mNone\u001b[39;00m:\n",
      "\u001b[1;31mInvalidArgumentError\u001b[0m: Graph execution error:\n\nDetected at node 'sequential_1/embedding_1/embedding_lookup' defined at (most recent call last):\n    File \"c:\\Anaconda3\\envs\\TF_D\\lib\\runpy.py\", line 197, in _run_module_as_main\n      return _run_code(code, main_globals, None,\n    File \"c:\\Anaconda3\\envs\\TF_D\\lib\\runpy.py\", line 87, in _run_code\n      exec(code, run_globals)\n    File \"c:\\Anaconda3\\envs\\TF_D\\lib\\site-packages\\ipykernel_launcher.py\", line 18, in <module>\n      app.launch_new_instance()\n    File \"c:\\Anaconda3\\envs\\TF_D\\lib\\site-packages\\traitlets\\config\\application.py\", line 1075, in launch_instance\n      app.start()\n    File \"c:\\Anaconda3\\envs\\TF_D\\lib\\site-packages\\ipykernel\\kernelapp.py\", line 739, in start\n      self.io_loop.start()\n    File \"c:\\Anaconda3\\envs\\TF_D\\lib\\site-packages\\tornado\\platform\\asyncio.py\", line 205, in start\n      self.asyncio_loop.run_forever()\n    File \"c:\\Anaconda3\\envs\\TF_D\\lib\\asyncio\\base_events.py\", line 601, in run_forever\n      self._run_once()\n    File \"c:\\Anaconda3\\envs\\TF_D\\lib\\asyncio\\base_events.py\", line 1905, in _run_once\n      handle._run()\n    File \"c:\\Anaconda3\\envs\\TF_D\\lib\\asyncio\\events.py\", line 80, in _run\n      self._context.run(self._callback, *self._args)\n    File \"c:\\Anaconda3\\envs\\TF_D\\lib\\site-packages\\ipykernel\\kernelbase.py\", line 545, in dispatch_queue\n      await self.process_one()\n    File \"c:\\Anaconda3\\envs\\TF_D\\lib\\site-packages\\ipykernel\\kernelbase.py\", line 534, in process_one\n      await dispatch(*args)\n    File \"c:\\Anaconda3\\envs\\TF_D\\lib\\site-packages\\ipykernel\\kernelbase.py\", line 437, in dispatch_shell\n      await result\n    File \"c:\\Anaconda3\\envs\\TF_D\\lib\\site-packages\\ipykernel\\ipkernel.py\", line 362, in execute_request\n      await super().execute_request(stream, ident, parent)\n    File \"c:\\Anaconda3\\envs\\TF_D\\lib\\site-packages\\ipykernel\\kernelbase.py\", line 778, in execute_request\n      reply_content = await reply_content\n    File \"c:\\Anaconda3\\envs\\TF_D\\lib\\site-packages\\ipykernel\\ipkernel.py\", line 449, in do_execute\n      res = shell.run_cell(\n    File \"c:\\Anaconda3\\envs\\TF_D\\lib\\site-packages\\ipykernel\\zmqshell.py\", line 549, in run_cell\n      return super().run_cell(*args, **kwargs)\n    File \"c:\\Anaconda3\\envs\\TF_D\\lib\\site-packages\\IPython\\core\\interactiveshell.py\", line 3048, in run_cell\n      result = self._run_cell(\n    File \"c:\\Anaconda3\\envs\\TF_D\\lib\\site-packages\\IPython\\core\\interactiveshell.py\", line 3103, in _run_cell\n      result = runner(coro)\n    File \"c:\\Anaconda3\\envs\\TF_D\\lib\\site-packages\\IPython\\core\\async_helpers.py\", line 129, in _pseudo_sync_runner\n      coro.send(None)\n    File \"c:\\Anaconda3\\envs\\TF_D\\lib\\site-packages\\IPython\\core\\interactiveshell.py\", line 3308, in run_cell_async\n      has_raised = await self.run_ast_nodes(code_ast.body, cell_name,\n    File \"c:\\Anaconda3\\envs\\TF_D\\lib\\site-packages\\IPython\\core\\interactiveshell.py\", line 3490, in run_ast_nodes\n      if await self.run_code(code, result, async_=asy):\n    File \"c:\\Anaconda3\\envs\\TF_D\\lib\\site-packages\\IPython\\core\\interactiveshell.py\", line 3550, in run_code\n      exec(code_obj, self.user_global_ns, self.user_ns)\n    File \"C:\\Users\\Vandan Patel\\AppData\\Local\\Temp\\ipykernel_23896\\873758998.py\", line 1, in <module>\n      model.fit(X_train, y_train, epochs=5, batch_size=32, validation_data=(X_test, y_test), verbose=2)\n    File \"c:\\Anaconda3\\envs\\TF_D\\lib\\site-packages\\keras\\utils\\traceback_utils.py\", line 65, in error_handler\n      return fn(*args, **kwargs)\n    File \"c:\\Anaconda3\\envs\\TF_D\\lib\\site-packages\\keras\\engine\\training.py\", line 1650, in fit\n      tmp_logs = self.train_function(iterator)\n    File \"c:\\Anaconda3\\envs\\TF_D\\lib\\site-packages\\keras\\engine\\training.py\", line 1249, in train_function\n      return step_function(self, iterator)\n    File \"c:\\Anaconda3\\envs\\TF_D\\lib\\site-packages\\keras\\engine\\training.py\", line 1233, in step_function\n      outputs = model.distribute_strategy.run(run_step, args=(data,))\n    File \"c:\\Anaconda3\\envs\\TF_D\\lib\\site-packages\\keras\\engine\\training.py\", line 1222, in run_step\n      outputs = model.train_step(data)\n    File \"c:\\Anaconda3\\envs\\TF_D\\lib\\site-packages\\keras\\engine\\training.py\", line 1023, in train_step\n      y_pred = self(x, training=True)\n    File \"c:\\Anaconda3\\envs\\TF_D\\lib\\site-packages\\keras\\utils\\traceback_utils.py\", line 65, in error_handler\n      return fn(*args, **kwargs)\n    File \"c:\\Anaconda3\\envs\\TF_D\\lib\\site-packages\\keras\\engine\\training.py\", line 561, in __call__\n      return super().__call__(*args, **kwargs)\n    File \"c:\\Anaconda3\\envs\\TF_D\\lib\\site-packages\\keras\\utils\\traceback_utils.py\", line 65, in error_handler\n      return fn(*args, **kwargs)\n    File \"c:\\Anaconda3\\envs\\TF_D\\lib\\site-packages\\keras\\engine\\base_layer.py\", line 1132, in __call__\n      outputs = call_fn(inputs, *args, **kwargs)\n    File \"c:\\Anaconda3\\envs\\TF_D\\lib\\site-packages\\keras\\utils\\traceback_utils.py\", line 96, in error_handler\n      return fn(*args, **kwargs)\n    File \"c:\\Anaconda3\\envs\\TF_D\\lib\\site-packages\\keras\\engine\\sequential.py\", line 413, in call\n      return super().call(inputs, training=training, mask=mask)\n    File \"c:\\Anaconda3\\envs\\TF_D\\lib\\site-packages\\keras\\engine\\functional.py\", line 511, in call\n      return self._run_internal_graph(inputs, training=training, mask=mask)\n    File \"c:\\Anaconda3\\envs\\TF_D\\lib\\site-packages\\keras\\engine\\functional.py\", line 668, in _run_internal_graph\n      outputs = node.layer(*args, **kwargs)\n    File \"c:\\Anaconda3\\envs\\TF_D\\lib\\site-packages\\keras\\utils\\traceback_utils.py\", line 65, in error_handler\n      return fn(*args, **kwargs)\n    File \"c:\\Anaconda3\\envs\\TF_D\\lib\\site-packages\\keras\\engine\\base_layer.py\", line 1132, in __call__\n      outputs = call_fn(inputs, *args, **kwargs)\n    File \"c:\\Anaconda3\\envs\\TF_D\\lib\\site-packages\\keras\\utils\\traceback_utils.py\", line 96, in error_handler\n      return fn(*args, **kwargs)\n    File \"c:\\Anaconda3\\envs\\TF_D\\lib\\site-packages\\keras\\layers\\core\\embedding.py\", line 208, in call\n      out = tf.nn.embedding_lookup(self.embeddings, inputs)\nNode: 'sequential_1/embedding_1/embedding_lookup'\nindices[0,1] = 14551 is not in [0, 10000)\n\t [[{{node sequential_1/embedding_1/embedding_lookup}}]] [Op:__inference_train_function_6972]"
     ]
    }
   ],
   "source": [
    "model.fit(X_train, y_train, epochs=10, batch_size=5, validation_data=(X_test, y_test))"
   ]
  },
  {
   "cell_type": "code",
   "execution_count": null,
   "metadata": {},
   "outputs": [],
   "source": []
  }
 ],
 "metadata": {
  "kernelspec": {
   "display_name": "TF_D",
   "language": "python",
   "name": "python3"
  },
  "language_info": {
   "codemirror_mode": {
    "name": "ipython",
    "version": 3
   },
   "file_extension": ".py",
   "mimetype": "text/x-python",
   "name": "python",
   "nbconvert_exporter": "python",
   "pygments_lexer": "ipython3",
   "version": "3.9.20"
  }
 },
 "nbformat": 4,
 "nbformat_minor": 2
}
